Workbook

Sheet Bilgi
A1: PROJE ÖZETİ
A3: Proje | B3: AHP + TOPSIS + ELECTRE ile E-Ticaret Sitelerinin Performans Değerlendirmesi
A4: Öğrenci | B4: Büşra Nur Yıldırım
A5: Öğrenci No | B5: 230326759
A6: Grup | B6: Kırmızı Grup (Anket sırası 1-34)
A7: Ders | B7: YBS302 - Karar Destek Sistemleri
A8: Öğretim Üyesi | B8: Dr. Öğr. Üyesi Neda Alipour
A9: Üniversite | B9: İstanbul Gelişim Üniversitesi
A10: Dönem | B10: Bahar 2025-2026
A12: Kriter Sayısı | B12: 5
A13: Alternatif Sayısı | B13: 6
A14: Toplam Katılımcı | B14: Anket_Yanıtları sayfasına bakınız
A15: Tutarlılık Eşiği (CR) | B15: ≤ 0.10
A16: RI (n=5) | B16: 1.11
A18: Çalışma Akışı
A19: 1 | B19: Her katılımcı için ikili karşılaştırma matrisi (Saaty 1-9 skalası)
A20: 2 | B20: Sütun normalizasyonu → Öz Vektör (ÖZV / kriter ağırlıkları)
A21: 3 | B21: λ_max (ENBÖZD) → CI = (λ_max - n)/(n-1) → CR = CI/RI
A22: 4 | B22: CR ≤ 0.10 olan katılımcılar tutarlı kabul edilir (≥ 20 olmalı)
A23: 5 | B23: Tutarlı katılımcıların ağırlıkları GEOMETRİK ORTALAMA ile birleştirilir
A24: 6 | B24: Alternatif performans puanları ARİTMETİK ORTALAMA ile birleştirilir
A25: 7 | B25: TOPSIS ve ELECTRE birleştirilmiş veri üzerinde BİRER KEZ çalıştırılır
A26: 8 | B26: Tüm hücreler formül, hiçbir ara değer elle yazılmamıştır
A28: Notlar
A29: Kriterler | B29: Tüm kriterler FAYDA tipindedir (yüksek = iyi)
A30: 'Kullanmıyorum' | B30: Aritmetik ortalamada bu cevap dahil edilmez
A31: Veri Kaynağı | B31: Google Forms canlı anket çıktısı (SURVEY.md)

Sheet Anket_Yanitlari
A1: participant_id | B1: cinsiyet | C1: yas | D1: egitim | E1: meslek | F1: alisveris_sikligi | G1: cihaz | H1: ahp_01 | I1: ahp_02 | J1: ahp_03 | K1: ahp_04 | L1: ahp_05 | M1: ahp_06 | N1: ahp_07 | O1: ahp_08 | P1: ahp_09 | Q1: ahp_10 | R1: topsis_K1_A1 | S1: topsis_K1_A2 | T1: topsis_K1_A3 | U1: topsis_K1_A4 | V1: topsis_K1_A5 | W1: topsis_K1_A6 | X1: topsis_K2_A1 | Y1: topsis_K2_A2 | Z1: topsis_K2_A3 | AA1: topsis_K2_A4 | AB1: topsis_K2_A5 | AC1: topsis_K2_A6 | AD1: topsis_K3_A1 | AE1: topsis_K3_A2 | AF1: topsis_K3_A3 | AG1: topsis_K3_A4 | AH1: topsis_K3_A5 | AI1: topsis_K3_A6 | AJ1: topsis_K4_A1 | AK1: topsis_K4_A2 | AL1: topsis_K4_A3 | AM1: topsis_K4_A4 | AN1: topsis_K4_A5 | AO1: topsis_K4_A6 | AP1: topsis_K5_A1 | AQ1: topsis_K5_A2 | AR1: topsis_K5_A3 | AS1: topsis_K5_A4 | AT1: topsis_K5_A5 | AU1: topsis_K5_A6
A2: 1 | B2: Kadın | C2: 18-24 | D2: Lise | E2: Kamu | F2: Ayda birkaç kez | G2: Mobil uygulama | H2: 1 | I2: 1 | J2: 3 | K2: 1 | L2: 1 | M2: 3 | N2: 1 | O2: 1 | P2: 0.33333333 | Q2: 0.33333333 | R2: 70 | S2: 70 | T2: Kullanmıyorum | U2: 40 | V2: 70 | W2: 80 | X2: 70 | Y2: Kullanmıyorum | Z2: 80 | AA2: 60 | AB2: 90 | AC2: 80 | AD2: 80 | AE2: 60 | AF2: 80 | AG2: Kullanmıyorum | AH2: 70 | AI2: 60 | AJ2: 70 | AK2: 60 | AL2: 70 | AM2: 50 | AN2: 80 | AO2: 80 | AP2: 80 | AQ2: 70 | AR2: 80 | AS2: 80 | AT2: 60 | AU2: 80
A3: 2 | B3: Erkek | C3: 25-34 | D3: Lisans | E3: Kamu | F3: Haftada birkaç kez | G3: Tablet | H3: 1 | I3: 0.33333333 | J3: 1 | K3: 0.33333333 | L3: 0.33333333 | M3: 1 | N3: 0.33333333 | O3: 3 | P3: 1 | Q3: 0.33333333 | R3: 70 | S3: 60 | T3: 90 | U3: Kullanmıyorum | V3: 90 | W3: 90 | X3: 80 | Y3: 60 | Z3: 80 | AA3: 40 | AB3: 70 | AC3: 70 | AD3: Kullanmıyorum | AE3: 50 | AF3: 90 | AG3: 50 | AH3: 70 | AI3: 90 | AJ3: 80 | AK3: 60 | AL3: 70 | AM3: 60 | AN3: 80 | AO3: 80 | AP3: 70 | AQ3: 60 | AR3: 80 | AS3: 60 | AT3: 50 | AU3: 80
A4: 3 | B4: Erkek | C4: 18-24 | D4: Lisans | E4: Öğrenci | F4: Haftada bir | G4: Mobil uygulama | H4: 3 | I4: 1 | J4: 1 | K4: 0.33333333 | L4: 0.33333333 | M4: 0.33333333 | N4: 0.33333333 | O4: 1 | P4: 5 | Q4: 5 | R4: 80 | S4: 60 | T4: 80 | U4: 50 | V4: Kullanmıyorum | W4: 80 | X4: 80 | Y4: 70 | Z4: 70 | AA4: 30 | AB4: 80 | AC4: 100 | AD4: 70 | AE4: 60 | AF4: 80 | AG4: 50 | AH4: 70 | AI4: 90 | AJ4: 70 | AK4: 60 | AL4: 70 | AM4: 50 | AN4: 80 | AO4: 100 | AP4: 70 | AQ4: 60 | AR4: 80 | AS4: 60 | AT4: 60 | AU4: 80
A5: 4 | B5: Kadın | C5: 45-54 | D5: Lisans | E5: Serbest Meslek | F5: Haftada bir | G5: Mobil tarayıcı | H5: 5 | I5: 3 | J5: 3 | K5: 1 | L5: 0.33333333 | M5: 1 | N5: 0.33333333 | O5: 0.2 | P5: 5 | Q5: 3 | R5: 70 | S5: 50 | T5: 80 | U5: 60 | V5: 60 | W5: 100 | X5: 100 | Y5: 60 | Z5: 80 | AA5: 50 | AB5: 80 | AC5: 90 | AD5: Kullanmıyorum | AE5: 60 | AF5: 80 | AG5: 50 | AH5: 80 | AI5: 80 | AJ5: 80 | AK5: 70 | AL5: 90 | AM5: 50 | AN5: 70 | AO5: 80 | AP5: 80 | AQ5: 60 | AR5: 80 | AS5: 70 | AT5: 50 | AU5: 80
A6: 5 | B6: Erkek | C6: 18-24 | D6: Lisans | E6: Özel Sektör | F6: Haftada bir | G6: Mobil uygulama | H6: 1 | I6: 0.33333333 | J6: 1 | K6: 0.33333333 | L6: 3 | M6: 1 | N6: 0.33333333 | O6: 1 | P6: 0.33333333 | Q6: 0.33333333 | R6: 80 | S6: 50 | T6: 70 | U6: 60 | V6: 70 | W6: 90 | X6: 90 | Y6: 50 | Z6: 80 | AA6: 60 | AB6: 80 | AC6: 90 | AD6: 70 | AE6: 70 | AF6: 60 | AG6: 50 | AH6: 60 | AI6: 90 | AJ6: 90 | AK6: 60 | AL6: 70 | AM6: 40 | AN6: 60 | AO6: 100 | AP6: 80 | AQ6: 50 | AR6: 70 | AS6: 50 | AT6: 60 | AU6: 80
A7: 6 | B7: Kadın | C7: 18-24 | D7: Ön Lisans | E7: Serbest Meslek | F7: Ayda bir | G7: Mobil tarayıcı | H7: 0.33333333 | I7: 5 | J7: 0.2 | K7: 0.33333333 | L7: 0.33333333 | M7: 1 | N7: 0.33333333 | O7: 1 | P7: 1 | Q7: 3 | R7: 80 | S7: 60 | T7: Kullanmıyorum | U7: 50 | V7: 70 | W7: 90 | X7: 80 | Y7: 70 | Z7: 100 | AA7: 60 | AB7: 90 | AC7: 90 | AD7: 70 | AE7: 60 | AF7: 70 | AG7: 50 | AH7: 80 | AI7: 70 | AJ7: 80 | AK7: Kullanmıyorum | AL7: Kullanmıyorum | AM7: 70 | AN7: 70 | AO7: 80 | AP7: 90 | AQ7: 60 | AR7: 70 | AS7: 50 | AT7: 60 | AU7: 90
A8: 7 | B8: Erkek | C8: 25-34 | D8: Ön Lisans | E8: Kamu | F8: Haftada birkaç kez | G8: Mobil uygulama | H8: 1 | I8: 1 | J8: 1 | K8: 1 | L8: 1 | M8: 1 | N8: 0.33333333 | O8: 1 | P8: 0.33333333 | Q8: 0.33333333 | R8: 80 | S8: 70 | T8: 70 | U8: 60 | V8: 70 | W8: 90 | X8: 80 | Y8: 70 | Z8: 70 | AA8: 60 | AB8: 80 | AC8: 80 | AD8: 90 | AE8: 60 | AF8: 80 | AG8: 30 | AH8: 60 | AI8: 80 | AJ8: 90 | AK8: 50 | AL8: 80 | AM8: 50 | AN8: 80 | AO8: 80 | AP8: 80 | AQ8: 70 | AR8: 80 | AS8: 50 | AT8: 40 | AU8: 80
A9: 8 | B9: Kadın | C9: 18-24 | D9: Lise | E9: Öğrenci | F9: Haftada birkaç kez | G9: Tablet | H9: 0.2 | I9: 1 | J9: 1 | K9: 0.33333333 | L9: 1 | M9: 3 | N9: 3 | O9: 1 | P9: 3 | Q9: 5 | R9: 70 | S9: 50 | T9: 70 | U9: 50 | V9: 70 | W9: 90 | X9: 90 | Y9: Kullanmıyorum | Z9: 80 | AA9: 60 | AB9: 90 | AC9: 90 | AD9: 70 | AE9: 60 | AF9: 90 | AG9: 60 | AH9: 70 | AI9: 70 | AJ9: 90 | AK9: Kullanmıyorum | AL9: 80 | AM9: 40 | AN9: 70 | AO9: 90 | AP9: 80 | AQ9: 60 | AR9: 80 | AS9: 50 | AT9: 50 | AU9: 80
A10: 9 | B10: Erkek | C10: 18-24 | D10: Ön Lisans | E10: Öğrenci | F10: Ayda birkaç kez | G10: Mobil uygulama | H10: 1 | I10: 1 | J10: 3 | K10: 1 | L10: 1 | M10: 3 | N10: 1 | O10: 3 | P10: 1 | Q10: 0.33333333 | R10: 80 | S10: 60 | T10: 90 | U10: 60 | V10: 60 | W10: 90 | X10: 70 | Y10: 60 | Z10: 90 | AA10: 50 | AB10: 70 | AC10: 90 | AD10: 70 | AE10: 60 | AF10: 90 | AG10: 50 | AH10: 80 | AI10: 80 | AJ10: 80 | AK10: 60 | AL10: 60 | AM10: 30 | AN10: 70 | AO10: 90 | AP10: 80 | AQ10: 60 | AR10: 70 | AS10: 70 | AT10: 60 | AU10: 50
A11: 10 | B11: Erkek | C11: 25-34 | D11: Yüksek Lisans | E11: Öğrenci | F11: Daha az | G11: Mobil tarayıcı | H11: 1 | I11: 0.33333333 | J11: 5 | K11: 1 | L11: 0.33333333 | M11: 3 | N11: 1 | O11: 5 | P11: 1 | Q11: 0.2 | R11: 80 | S11: 60 | T11: 60 | U11: 50 | V11: 70 | W11: 100 | X11: 80 | Y11: 60 | Z11: 80 | AA11: 60 | AB11: 80 | AC11: 90 | AD11: 80 | AE11: 50 | AF11: 90 | AG11: 50 | AH11: 70 | AI11: 70 | AJ11: 90 | AK11: 60 | AL11: 70 | AM11: 40 | AN11: 70 | AO11: 90 | AP11: Kullanmıyorum | AQ11: 60 | AR11: 70 | AS11: 60 | AT11: 50 | AU11: 80
A12: 11 | B12: Erkek | C12: 18-24 | D12: Lisans | E12: Öğrenci | F12: Ayda birkaç kez | G12: Mobil uygulama | H12: 0.33333333 | I12: 0.33333333 | J12: 1 | K12: 0.33333333 | L12: 1 | M12: 3 | N12: 1 | O12: 0.33333333 | P12: 1 | Q12: 0.33333333 | R12: 80 | S12: 50 | T12: 70 | U12: 60 | V12: 70 | W12: 100 | X12: Kullanmıyorum | Y12: 50 | Z12: 70 | AA12: 40 | AB12: 70 | AC12: 80 | AD12: 70 | AE12: 60 | AF12: 70 | AG12: 50 | AH12: 60 | AI12: 80 | AJ12: 90 | AK12: 70 | AL12: Kullanmıyorum | AM12: 50 | AN12: 70 | AO12: 80 | AP12: 90 | AQ12: 60 | AR12: 80 | AS12: Kullanmıyorum | AT12: 60 | AU12: 60
A13: 12 | B13: Kadın | C13: 35-44 | D13: Lisans | E13: Özel Sektör | F13: Haftada birkaç kez | G13: Mobil uygulama | H13: 1 | I13: 1 | J13: 1 | K13: 1 | L13: 0.33333333 | M13: 0.33333333 | N13: 0.33333333 | O13: 1 | P13: 1 | Q13: 1 | R13: 90 | S13: 60 | T13: 70 | U13: Kullanmıyorum | V13: 60 | W13: 90 | X13: 80 | Y13: 70 | Z13: 70 | AA13: 40 | AB13: 90 | AC13: 80 | AD13: 50 | AE13: 60 | AF13: 70 | AG13: 60 | AH13: 70 | AI13: 80 | AJ13: 80 | AK13: 70 | AL13: 70 | AM13: Kullanmıyorum | AN13: 70 | AO13: 90 | AP13: 70 | AQ13: 60 | AR13: 70 | AS13: 40 | AT13: 60 | AU13: 80
A14: 13 | B14: Kadın | C14: 35-44 | D14: Ön Lisans | E14: Öğrenci | F14: Ayda birkaç kez | G14: Mobil uygulama | H14: 1 | I14: 1 | J14: 1 | K14: 0.33333333 | L14: 0.2 | M14: 3 | N14: 1 | O14: 1 | P14: 0.33333333 | Q14: 5 | R14: 70 | S14: 60 | T14: 90 | U14: 50 | V14: 70 | W14: 70 | X14: 80 | Y14: 50 | Z14: 70 | AA14: 50 | AB14: 70 | AC14: 80 | AD14: 80 | AE14: 60 | AF14: 90 | AG14: 60 | AH14: 70 | AI14: 90 | AJ14: 80 | AK14: 70 | AL14: 70 | AM14: 50 | AN14: 80 | AO14: 90 | AP14: 80 | AQ14: 60 | AR14: 70 | AS14: 70 | AT14: 60 | AU14: 70
A15: 14 | B15: Kadın | C15: 18-24 | D15: Ön Lisans | E15: Özel Sektör | F15: Ayda birkaç kez | G15: Mobil uygulama | H15: 3 | I15: 1 | J15: 3 | K15: 1 | L15: 0.33333333 | M15: 1 | N15: 0.33333333 | O15: 5 | P15: 1 | Q15: 0.2 | R15: 70 | S15: 60 | T15: 90 | U15: 60 | V15: 70 | W15: 80 | X15: 70 | Y15: 60 | Z15: 90 | AA15: 50 | AB15: 70 | AC15: 90 | AD15: 80 | AE15: Kullanmıyorum | AF15: 70 | AG15: 60 | AH15: 70 | AI15: 90 | AJ15: 80 | AK15: 60 | AL15: 80 | AM15: 60 | AN15: 70 | AO15: 80 | AP15: 70 | AQ15: 60 | AR15: 80 | AS15: 50 | AT15: 70 | AU15: 80
A16: 15 | B16: Erkek | C16: 25-34 | D16: Ön Lisans | E16: Emekli | F16: Daha az | G16: Masaüstü tarayıcı | H16: 1 | I16: 1 | J16: 1 | K16: 0.33333333 | L16: 1 | M16: 1 | N16: 1 | O16: 1 | P16: 0.33333333 | Q16: 0.33333333 | R16: 90 | S16: 60 | T16: 90 | U16: Kullanmıyorum | V16: 70 | W16: 70 | X16: 80 | Y16: 50 | Z16: 80 | AA16: 50 | AB16: 80 | AC16: Kullanmıyorum | AD16: 70 | AE16: 60 | AF16: 70 | AG16: 60 | AH16: 80 | AI16: 70 | AJ16: 80 | AK16: 70 | AL16: 80 | AM16: 60 | AN16: 80 | AO16: 70 | AP16: 90 | AQ16: 70 | AR16: 80 | AS16: 50 | AT16: 60 | AU16: Kullanmıyorum
A17: 16 | B17: Erkek | C17: 25-34 | D17: Yüksek Lisans | E17: Özel Sektör | F17: Ayda birkaç kez | G17: Tablet | H17: 1 | I17: 1 | J17: 3 | K17: 1 | L17: 1 | M17: 3 | N17: 1 | O17: 3 | P17: 1 | Q17: 0.33333333 | R17: 70 | S17: 70 | T17: 70 | U17: 70 | V17: Kullanmıyorum | W17: 90 | X17: 80 | Y17: 60 | Z17: 90 | AA17: 40 | AB17: 70 | AC17: 100 | AD17: 90 | AE17: 50 | AF17: 90 | AG17: 50 | AH17: 60 | AI17: 80 | AJ17: 80 | AK17: 60 | AL17: 80 | AM17: 50 | AN17: 80 | AO17: 80 | AP17: 90 | AQ17: 70 | AR17: 70 | AS17: 60 | AT17: 60 | AU17: 70
A18: 17 | B18: Kadın | C18: 25-34 | D18: Lisans | E18: Öğrenci | F18: Haftada bir | G18: Mobil tarayıcı | H18: 1 | I18: 0.33333333 | J18: 1 | K18: 0.33333333 | L18: 0.33333333 | M18: 1 | N18: 0.33333333 | O18: 1 | P18: 1 | Q18: 0.33333333 | R18: 90 | S18: 60 | T18: 70 | U18: 70 | V18: 90 | W18: 80 | X18: 70 | Y18: 60 | Z18: 70 | AA18: 60 | AB18: 70 | AC18: 80 | AD18: 60 | AE18: 50 | AF18: 70 | AG18: 60 | AH18: 70 | AI18: 90 | AJ18: 80 | AK18: 60 | AL18: 80 | AM18: 40 | AN18: 90 | AO18: 80 | AP18: 90 | AQ18: 80 | AR18: 70 | AS18: 50 | AT18: 60 | AU18: 70
A19: 18 | B19: Kadın | C19: 55+ | D19: Lise | E19: Öğrenci | F19: Ayda bir | G19: Mobil tarayıcı | H19: 1 | I19: 1 | J19: 1 | K19: 0.33333333 | L19: 3 | M19: 1 | N19: 0.33333333 | O19: 1 | P19: 0.33333333 | Q19: 0.33333333 | R19: Kullanmıyorum | S19: 60 | T19: 80 | U19: 60 | V19: Kullanmıyorum | W19: 70 | X19: 90 | Y19: 60 | Z19: 90 | AA19: 50 | AB19: Kullanmıyorum | AC19: 80 | AD19: 80 | AE19: 60 | AF19: Kullanmıyorum | AG19: 50 | AH19: 90 | AI19: 80 | AJ19: 80 | AK19: 60 | AL19: 80 | AM19: Kullanmıyorum | AN19: 70 | AO19: 80 | AP19: 80 | AQ19: Kullanmıyorum | AR19: Kullanmıyorum | AS19: 50 | AT19: 60 | AU19: 60
A20: 19 | B20: Belirtmek istemiyorum | C20: 18-24 | D20: Lisans | E20: Özel Sektör | F20: Ayda birkaç kez | G20: Mobil uygulama | H20: 1 | I20: 1 | J20: 1 | K20: 1 | L20: 0.33333333 | M20: 1 | N20: 0.33333333 | O20: 1 | P20: 1 | Q20: 0.33333333 | R20: 90 | S20: 70 | T20: 100 | U20: 50 | V20: 70 | W20: 80 | X20: 90 | Y20: 70 | Z20: 70 | AA20: 40 | AB20: 60 | AC20: 80 | AD20: 80 | AE20: 40 | AF20: 80 | AG20: 50 | AH20: 80 | AI20: 90 | AJ20: 80 | AK20: 60 | AL20: 80 | AM20: 50 | AN20: 80 | AO20: 80 | AP20: 80 | AQ20: 60 | AR20: 80 | AS20: 40 | AT20: 60 | AU20: 70
A21: 20 | B21: Kadın | C21: 25-34 | D21: Lisans | E21: Özel Sektör | F21: Ayda birkaç kez | G21: Mobil uygulama | H21: 1 | I21: 1 | J21: 1 | K21: 0.33333333 | L21: 0.33333333 | M21: 1 | N21: 0.33333333 | O21: 3 | P21: 1 | Q21: 0.33333333 | R21: 60 | S21: 70 | T21: 80 | U21: 50 | V21: 70 | W21: 90 | X21: 90 | Y21: 70 | Z21: 90 | AA21: 50 | AB21: 60 | AC21: 80 | AD21: 80 | AE21: Kullanmıyorum | AF21: 90 | AG21: 50 | AH21: 70 | AI21: 80 | AJ21: 90 | AK21: 50 | AL21: 70 | AM21: 50 | AN21: 80 | AO21: 80 | AP21: 80 | AQ21: 60 | AR21: 80 | AS21: 60 | AT21: 60 | AU21: 70
A22: 21 | B22: Kadın | C22: 25-34 | D22: Lisans | E22: Öğrenci | F22: Haftada birkaç kez | G22: Tablet | H22: 5 | I22: 1 | J22: 0.33333333 | K22: 5 | L22: 5 | M22: 3 | N22: 5 | O22: 0.33333333 | P22: 0.2 | Q22: 3 | R22: 90 | S22: 60 | T22: 80 | U22: 50 | V22: 80 | W22: 80 | X22: 90 | Y22: 60 | Z22: 80 | AA22: 40 | AB22: 80 | AC22: 80 | AD22: 80 | AE22: Kullanmıyorum | AF22: 90 | AG22: 50 | AH22: 70 | AI22: 70 | AJ22: 60 | AK22: 60 | AL22: 70 | AM22: 50 | AN22: 80 | AO22: 80 | AP22: 70 | AQ22: 70 | AR22: 80 | AS22: 60 | AT22: 50 | AU22: 70
A23: 22 | B23: Kadın | C23: 25-34 | D23: Lisans | E23: Özel Sektör | F23: Haftada birkaç kez | G23: Mobil uygulama | H23: 1 | I23: 0.33333333 | J23: 1 | K23: 1 | L23: 1 | M23: 1 | N23: 1 | O23: 1 | P23: 1 | Q23: 1 | R23: 80 | S23: 60 | T23: 80 | U23: 50 | V23: 70 | W23: 100 | X23: 80 | Y23: 60 | Z23: 70 | AA23: 50 | AB23: 90 | AC23: 90 | AD23: Kullanmıyorum | AE23: 50 | AF23: 90 | AG23: 60 | AH23: 80 | AI23: 70 | AJ23: 70 | AK23: 70 | AL23: 80 | AM23: 50 | AN23: 70 | AO23: 80 | AP23: 100 | AQ23: 60 | AR23: 60 | AS23: 50 | AT23: 60 | AU23: 90
A24: 23 | B24: Kadın | C24: 25-34 | D24: Lisans | E24: Öğrenci | F24: Haftada bir | G24: Mobil uygulama | H24: 0.2 | I24: 0.33333333 | J24: 0.33333333 | K24: 1 | L24: 3 | M24: 0.33333333 | N24: 3 | O24: 5 | P24: 3 | Q24: 0.33333333 | R24: 80 | S24: 70 | T24: 70 | U24: 70 | V24: Kullanmıyorum | W24: 80 | X24: 80 | Y24: 60 | Z24: 70 | AA24: 40 | AB24: 80 | AC24: 80 | AD24: 90 | AE24: 60 | AF24: 90 | AG24: 50 | AH24: 70 | AI24: 80 | AJ24: 80 | AK24: 70 | AL24: 80 | AM24: 40 | AN24: 80 | AO24: 80 | AP24: 80 | AQ24: 70 | AR24: 70 | AS24: 70 | AT24: 50 | AU24: 80
A25: 24 | B25: Kadın | C25: 25-34 | D25: Lisans | E25: Öğrenci | F25: Ayda birkaç kez | G25: Mobil uygulama | H25: 0.2 | I25: 1 | J25: 5 | K25: 1 | L25: 1 | M25: 3 | N25: 1 | O25: 3 | P25: 0.33333333 | Q25: 0.33333333 | R25: 80 | S25: 70 | T25: 90 | U25: 60 | V25: 80 | W25: 70 | X25: 100 | Y25: 70 | Z25: 90 | AA25: 50 | AB25: 60 | AC25: 80 | AD25: 60 | AE25: Kullanmıyorum | AF25: 70 | AG25: Kullanmıyorum | AH25: 70 | AI25: 70 | AJ25: 80 | AK25: 70 | AL25: 80 | AM25: 50 | AN25: 70 | AO25: 80 | AP25: 90 | AQ25: 70 | AR25: 70 | AS25: 50 | AT25: 70 | AU25: 70
A26: 25 | B26: Erkek | C26: 25-34 | D26: Lisans | E26: Özel Sektör | F26: Daha az | G26: Mobil tarayıcı | H26: 1 | I26: 0.33333333 | J26: 0.33333333 | K26: 0.33333333 | L26: 3 | M26: 0.33333333 | N26: 0.33333333 | O26: 3 | P26: 0.33333333 | Q26: 5 | R26: 70 | S26: 60 | T26: 70 | U26: 40 | V26: 60 | W26: 90 | X26: 100 | Y26: 60 | Z26: 80 | AA26: 50 | AB26: 90 | AC26: 90 | AD26: 70 | AE26: 60 | AF26: 80 | AG26: 70 | AH26: 80 | AI26: 90 | AJ26: 80 | AK26: 50 | AL26: 70 | AM26: 50 | AN26: 70 | AO26: 70 | AP26: 80 | AQ26: 50 | AR26: 70 | AS26: 40 | AT26: 70 | AU26: 60
A27: 26 | B27: Erkek | C27: 25-34 | D27: Lise | E27: Öğrenci | F27: Haftada birkaç kez | G27: Masaüstü tarayıcı | H27: 1 | I27: 0.33333333 | J27: 1 | K27: 0.33333333 | L27: 0.33333333 | M27: 1 | N27: 0.33333333 | O27: 3 | P27: 3 | Q27: 0.33333333 | R27: 60 | S27: 50 | T27: 80 | U27: 50 | V27: 70 | W27: 90 | X27: 100 | Y27: 50 | Z27: 80 | AA27: 50 | AB27: 70 | AC27: 80 | AD27: 60 | AE27: 50 | AF27: 80 | AG27: 50 | AH27: 70 | AI27: 80 | AJ27: 80 | AK27: 60 | AL27: 60 | AM27: 60 | AN27: 70 | AO27: 80 | AP27: 70 | AQ27: Kullanmıyorum | AR27: 70 | AS27: 60 | AT27: 60 | AU27: 80
A28: 27 | B28: Erkek | C28: 25-34 | D28: Lisans | E28: Serbest Meslek | F28: Ayda birkaç kez | G28: Mobil tarayıcı | H28: 1 | I28: 0.33333333 | J28: 3 | K28: 0.33333333 | L28: 0.33333333 | M28: 3 | N28: 0.33333333 | O28: 5 | P28: 1 | Q28: 0.2 | R28: 80 | S28: Kullanmıyorum | T28: 80 | U28: 60 | V28: 80 | W28: 70 | X28: 80 | Y28: 70 | Z28: 60 | AA28: 40 | AB28: 70 | AC28: 80 | AD28: 70 | AE28: 50 | AF28: 80 | AG28: 50 | AH28: 60 | AI28: 80 | AJ28: 80 | AK28: 60 | AL28: 80 | AM28: 50 | AN28: Kullanmıyorum | AO28: 80 | AP28: 100 | AQ28: 70 | AR28: 80 | AS28: 70 | AT28: 50 | AU28: 80
A29: 28 | B29: Erkek | C29: 25-34 | D29: Ön Lisans | E29: Diğer | F29: Haftada bir | G29: Mobil uygulama | H29: 1 | I29: 1 | J29: 1 | K29: 1 | L29: 1 | M29: 1 | N29: 1 | O29: 1 | P29: 1 | Q29: 0.33333333 | R29: 80 | S29: 60 | T29: 70 | U29: 70 | V29: 60 | W29: 80 | X29: 100 | Y29: 60 | Z29: 90 | AA29: 40 | AB29: 70 | AC29: Kullanmıyorum | AD29: 80 | AE29: 60 | AF29: 80 | AG29: 50 | AH29: 80 | AI29: 80 | AJ29: 70 | AK29: 60 | AL29: 70 | AM29: 60 | AN29: 80 | AO29: 70 | AP29: 90 | AQ29: 70 | AR29: 70 | AS29: 60 | AT29: 70 | AU29: 90
A30: 29 | B30: Kadın | C30: 25-34 | D30: Ön Lisans | E30: Öğrenci | F30: Haftada birkaç kez | G30: Mobil tarayıcı | H30: 1 | I30: 0.33333333 | J30: 3 | K30: 0.33333333 | L30: 0.33333333 | M30: 1 | N30: 0.2 | O30: 5 | P30: 1 | Q30: 0.2 | R30: 90 | S30: 60 | T30: Kullanmıyorum | U30: 50 | V30: 70 | W30: 100 | X30: 70 | Y30: 60 | Z30: 70 | AA30: 50 | AB30: 80 | AC30: 90 | AD30: 80 | AE30: Kullanmıyorum | AF30: 80 | AG30: Kullanmıyorum | AH30: 70 | AI30: 70 | AJ30: 80 | AK30: 50 | AL30: 80 | AM30: 40 | AN30: 80 | AO30: 80 | AP30: 80 | AQ30: 80 | AR30: 80 | AS30: 50 | AT30: 50 | AU30: 70
A31: 30 | B31: Kadın | C31: 55+ | D31: Lisans | E31: Emekli | F31: Ayda bir | G31: Masaüstü tarayıcı | H31: 1 | I31: 1 | J31: 3 | K31: 1 | L31: 1 | M31: 3 | N31: 1 | O31: 3 | P31: 0.33333333 | Q31: 0.2 | R31: 70 | S31: 50 | T31: 70 | U31: 50 | V31: 90 | W31: 70 | X31: 90 | Y31: 50 | Z31: 100 | AA31: 40 | AB31: 60 | AC31: Kullanmıyorum | AD31: Kullanmıyorum | AE31: 80 | AF31: 80 | AG31: 60 | AH31: 70 | AI31: 70 | AJ31: 70 | AK31: Kullanmıyorum | AL31: 80 | AM31: 60 | AN31: 90 | AO31: 90 | AP31: 70 | AQ31: 70 | AR31: 70 | AS31: 50 | AT31: 60 | AU31: 70
A32: 31 | B32: Erkek | C32: 18-24 | D32: Lisans | E32: Serbest Meslek | F32: Haftada bir | G32: Tablet | H32: 1 | I32: 1 | J32: 1 | K32: 1 | L32: 1 | M32: 1 | N32: 0.33333333 | O32: 1 | P32: 0.33333333 | Q32: 0.33333333 | R32: 80 | S32: 80 | T32: 80 | U32: 50 | V32: 70 | W32: 80 | X32: 80 | Y32: 60 | Z32: 80 | AA32: 50 | AB32: 70 | AC32: 80 | AD32: 90 | AE32: 60 | AF32: 90 | AG32: 40 | AH32: 60 | AI32: 80 | AJ32: 80 | AK32: 60 | AL32: 90 | AM32: 50 | AN32: 70 | AO32: 80 | AP32: 80 | AQ32: 60 | AR32: 80 | AS32: 60 | AT32: 60 | AU32: 80
A33: 32 | B33: Kadın | C33: 25-34 | D33: Lisans | E33: Öğrenci | F33: Ayda birkaç kez | G33: Mobil tarayıcı | H33: 1 | I33: 1 | J33: 0.33333333 | K33: 3 | L33: 1 | M33: 1 | N33: 1 | O33: 1 | P33: 0.33333333 | Q33: 1 | R33: 70 | S33: 50 | T33: 80 | U33: 50 | V33: 70 | W33: 90 | X33: 80 | Y33: 60 | Z33: 80 | AA33: 50 | AB33: 70 | AC33: 70 | AD33: 70 | AE33: 70 | AF33: Kullanmıyorum | AG33: 60 | AH33: 60 | AI33: 80 | AJ33: 90 | AK33: 60 | AL33: 80 | AM33: 40 | AN33: 70 | AO33: 80 | AP33: 70 | AQ33: 60 | AR33: 70 | AS33: 60 | AT33: 40 | AU33: 80
A34: 33 | B34: Erkek | C34: 25-34 | D34: Yüksek Lisans | E34: Serbest Meslek | F34: Haftada bir | G34: Mobil uygulama | H34: 3 | I34: 0.33333333 | J34: 1 | K34: 3 | L34: 0.2 | M34: 0.2 | N34: 0.2 | O34: 3 | P34: 1 | Q34: 0.33333333 | R34: 90 | S34: 50 | T34: 80 | U34: 60 | V34: 70 | W34: 90 | X34: 80 | Y34: 60 | Z34: 90 | AA34: 40 | AB34: 80 | AC34: 100 | AD34: 80 | AE34: 40 | AF34: 60 | AG34: 60 | AH34: 70 | AI34: 70 | AJ34: 80 | AK34: 70 | AL34: 70 | AM34: 50 | AN34: 80 | AO34: 80 | AP34: 80 | AQ34: 60 | AR34: 80 | AS34: 50 | AT34: 60 | AU34: 80
A35: 34 | B35: Kadın | C35: 55+ | D35: Lisans | E35: Öğrenci | F35: Ayda birkaç kez | G35: Mobil uygulama | H35: 1 | I35: 0.33333333 | J35: 1 | K35: 0.33333333 | L35: 1 | M35: 1 | N35: 0.33333333 | O35: 1 | P35: 1 | Q35: 0.33333333 | R35: 80 | S35: 50 | T35: 90 | U35: 40 | V35: 80 | W35: 90 | X35: 80 | Y35: 30 | Z35: 80 | AA35: 50 | AB35: 80 | AC35: Kullanmıyorum | AD35: 80 | AE35: 50 | AF35: 80 | AG35: 50 | AH35: 60 | AI35: 70 | AJ35: 80 | AK35: 70 | AL35: 60 | AM35: 50 | AN35: 60 | AO35: 80 | AP35: 80 | AQ35: 70 | AR35: 80 | AS35: 60 | AT35: 60 | AU35: 70
A36: 35 | B36: Erkek | C36: 25-34 | D36: Lisans | E36: Emekli | F36: Ayda birkaç kez | G36: Masaüstü tarayıcı | H36: 1 | I36: 1 | J36: 1 | K36: 1 | L36: 0.33333333 | M36: 1 | N36: 0.33333333 | O36: 3 | P36: 1 | Q36: 0.33333333 | R36: 60 | S36: 70 | T36: 80 | U36: 50 | V36: 70 | W36: 80 | X36: 80 | Y36: 50 | Z36: 80 | AA36: 60 | AB36: 70 | AC36: 90 | AD36: 80 | AE36: 60 | AF36: 80 | AG36: 60 | AH36: 60 | AI36: 80 | AJ36: 80 | AK36: 60 | AL36: 80 | AM36: 40 | AN36: 80 | AO36: 80 | AP36: 80 | AQ36: 70 | AR36: 60 | AS36: 50 | AT36: 60 | AU36: 70

Sheet Katilimci 01
A1: KATILIMCI 01 - AHP ANALİZİ
A3: Demografik Bilgiler
A4: Cinsiyet | B4: =Anket_Yanitlari!B2
A5: Yaş | B5: =Anket_Yanitlari!C2
A6: Eğitim | B6: =Anket_Yanitlari!D2
A7: Meslek | B7: =Anket_Yanitlari!E2
A8: Alışveriş Sıklığı | B8: =Anket_Yanitlari!F2
A9: Cihaz | B9: =Anket_Yanitlari!G2
A11: İkili Karşılaştırma Matrisi (A)
B12: Ödeme | C12: Kullanıcı Deneyimi | D12: Kargo | E12: Müşteri Yorumları | F12: Fiyatlandırma
A13: Ödeme | B13: 1 | C13: =Anket_Yanitlari!H2 | D13: =Anket_Yanitlari!I2 | E13: =Anket_Yanitlari!J2 | F13: =Anket_Yanitlari!K2
A14: Kullanıcı Deneyimi | B14: =1/C13 | C14: 1 | D14: =Anket_Yanitlari!L2 | E14: =Anket_Yanitlari!M2 | F14: =Anket_Yanitlari!N2
A15: Kargo | B15: =1/D13 | C15: =1/D14 | D15: 1 | E15: =Anket_Yanitlari!O2 | F15: =Anket_Yanitlari!P2
A16: Müşteri Yorumları | B16: =1/E13 | C16: =1/E14 | D16: =1/E15 | E16: 1 | F16: =Anket_Yanitlari!Q2
A17: Fiyatlandırma | B17: =1/F13 | C17: =1/F14 | D17: =1/F15 | E17: =1/F16 | F17: 1
A18: Sütun Toplamı | B18: =SUM(B13:B17) | C18: =SUM(C13:C17) | D18: =SUM(D13:D17) | E18: =SUM(E13:E17) | F18: =SUM(F13:F17)
A20: Normalize Matris (N)
B21: Ödeme | C21: Kullanıcı Deneyimi | D21: Kargo | E21: Müşteri Yorumları | F21: Fiyatlandırma
A22: Ödeme | B22: =B13/B18 | C22: =C13/C18 | D22: =D13/D18 | E22: =E13/E18 | F22: =F13/F18
A23: Kullanıcı Deneyimi | B23: =B14/B18 | C23: =C14/C18 | D23: =D14/D18 | E23: =E14/E18 | F23: =F14/F18
A24: Kargo | B24: =B15/B18 | C24: =C15/C18 | D24: =D15/D18 | E24: =E15/E18 | F24: =F15/F18
A25: Müşteri Yorumları | B25: =B16/B18 | C25: =C16/C18 | D25: =D16/D18 | E25: =E16/E18 | F25: =F16/F18
A26: Fiyatlandırma | B26: =B17/B18 | C26: =C17/C18 | D26: =D17/D18 | E26: =E17/E18 | F26: =F17/F18
A28: Kriter | B28: ÖZV (w) | C28: A·w | D28: A·w / w
A29: Ödeme | B29: =AVERAGE(B22:F22) | C29: =B13*$B$29+C13*$B$30+D13*$B$31+E13*$B$32+F13*$B$33 | D29: =C29/B29
A30: Kullanıcı Deneyimi | B30: =AVERAGE(B23:F23) | C30: =B14*$B$29+C14*$B$30+D14*$B$31+E14*$B$32+F14*$B$33 | D30: =C30/B30
A31: Kargo | B31: =AVERAGE(B24:F24) | C31: =B15*$B$29+C15*$B$30+D15*$B$31+E15*$B$32+F15*$B$33 | D31: =C31/B31
A32: Müşteri Yorumları | B32: =AVERAGE(B25:F25) | C32: =B16*$B$29+C16*$B$30+D16*$B$31+E16*$B$32+F16*$B$33 | D32: =C32/B32
A33: Fiyatlandırma | B33: =AVERAGE(B26:F26) | C33: =B17*$B$29+C17*$B$30+D17*$B$31+E17*$B$32+F17*$B$33 | D33: =C33/B33
A34: Toplam | B34: =SUM(B29:B33)
A36: λ_max (ENBÖZD) | B36: =AVERAGE(D29:D33)
A37: n (kriter sayısı) | B37: 5
A38: CI = (λ_max - n) / (n - 1) | B38: =(B36-B37)/(B37-1)
A39: RI (n=5) | B39: 1.11
A40: CR = CI / RI | B40: =B38/B39
A41: Tutarlılık Eşiği | B41: 0.1
A42: Durum | B42: =IF(B40<=B41,"Tutarlı","Tutarsız")

Sheet Katilimci 02
A1: KATILIMCI 02 - AHP ANALİZİ
A3: Demografik Bilgiler
A4: Cinsiyet | B4: =Anket_Yanitlari!B3
A5: Yaş | B5: =Anket_Yanitlari!C3
A6: Eğitim | B6: =Anket_Yanitlari!D3
A7: Meslek | B7: =Anket_Yanitlari!E3
A8: Alışveriş Sıklığı | B8: =Anket_Yanitlari!F3
A9: Cihaz | B9: =Anket_Yanitlari!G3
A11: İkili Karşılaştırma Matrisi (A)
B12: Ödeme | C12: Kullanıcı Deneyimi | D12: Kargo | E12: Müşteri Yorumları | F12: Fiyatlandırma
A13: Ödeme | B13: 1 | C13: =Anket_Yanitlari!H3 | D13: =Anket_Yanitlari!I3 | E13: =Anket_Yanitlari!J3 | F13: =Anket_Yanitlari!K3
A14: Kullanıcı Deneyimi | B14: =1/C13 | C14: 1 | D14: =Anket_Yanitlari!L3 | E14: =Anket_Yanitlari!M3 | F14: =Anket_Yanitlari!N3
A15: Kargo | B15: =1/D13 | C15: =1/D14 | D15: 1 | E15: =Anket_Yanitlari!O3 | F15: =Anket_Yanitlari!P3
A16: Müşteri Yorumları | B16: =1/E13 | C16: =1/E14 | D16: =1/E15 | E16: 1 | F16: =Anket_Yanitlari!Q3
A17: Fiyatlandırma | B17: =1/F13 | C17: =1/F14 | D17: =1/F15 | E17: =1/F16 | F17: 1
A18: Sütun Toplamı | B18: =SUM(B13:B17) | C18: =SUM(C13:C17) | D18: =SUM(D13:D17) | E18: =SUM(E13:E17) | F18: =SUM(F13:F17)
A20: Normalize Matris (N)
B21: Ödeme | C21: Kullanıcı Deneyimi | D21: Kargo | E21: Müşteri Yorumları | F21: Fiyatlandırma
A22: Ödeme | B22: =B13/B18 | C22: =C13/C18 | D22: =D13/D18 | E22: =E13/E18 | F22: =F13/F18
A23: Kullanıcı Deneyimi | B23: =B14/B18 | C23: =C14/C18 | D23: =D14/D18 | E23: =E14/E18 | F23: =F14/F18
A24: Kargo | B24: =B15/B18 | C24: =C15/C18 | D24: =D15/D18 | E24: =E15/E18 | F24: =F15/F18
A25: Müşteri Yorumları | B25: =B16/B18 | C25: =C16/C18 | D25: =D16/D18 | E25: =E16/E18 | F25: =F16/F18
A26: Fiyatlandırma | B26: =B17/B18 | C26: =C17/C18 | D26: =D17/D18 | E26: =E17/E18 | F26: =F17/F18
A28: Kriter | B28: ÖZV (w) | C28: A·w | D28: A·w / w
A29: Ödeme | B29: =AVERAGE(B22:F22) | C29: =B13*$B$29+C13*$B$30+D13*$B$31+E13*$B$32+F13*$B$33 | D29: =C29/B29
A30: Kullanıcı Deneyimi | B30: =AVERAGE(B23:F23) | C30: =B14*$B$29+C14*$B$30+D14*$B$31+E14*$B$32+F14*$B$33 | D30: =C30/B30
A31: Kargo | B31: =AVERAGE(B24:F24) | C31: =B15*$B$29+C15*$B$30+D15*$B$31+E15*$B$32+F15*$B$33 | D31: =C31/B31
A32: Müşteri Yorumları | B32: =AVERAGE(B25:F25) | C32: =B16*$B$29+C16*$B$30+D16*$B$31+E16*$B$32+F16*$B$33 | D32: =C32/B32
A33: Fiyatlandırma | B33: =AVERAGE(B26:F26) | C33: =B17*$B$29+C17*$B$30+D17*$B$31+E17*$B$32+F17*$B$33 | D33: =C33/B33
A34: Toplam | B34: =SUM(B29:B33)
A36: λ_max (ENBÖZD) | B36: =AVERAGE(D29:D33)
A37: n (kriter sayısı) | B37: 5
A38: CI = (λ_max - n) / (n - 1) | B38: =(B36-B37)/(B37-1)
A39: RI (n=5) | B39: 1.11
A40: CR = CI / RI | B40: =B38/B39
A41: Tutarlılık Eşiği | B41: 0.1
A42: Durum | B42: =IF(B40<=B41,"Tutarlı","Tutarsız")

Sheet Katilimci 03
A1: KATILIMCI 03 - AHP ANALİZİ
A3: Demografik Bilgiler
A4: Cinsiyet | B4: =Anket_Yanitlari!B4
A5: Yaş | B5: =Anket_Yanitlari!C4
A6: Eğitim | B6: =Anket_Yanitlari!D4
A7: Meslek | B7: =Anket_Yanitlari!E4
A8: Alışveriş Sıklığı | B8: =Anket_Yanitlari!F4
A9: Cihaz | B9: =Anket_Yanitlari!G4
A11: İkili Karşılaştırma Matrisi (A)
B12: Ödeme | C12: Kullanıcı Deneyimi | D12: Kargo | E12: Müşteri Yorumları | F12: Fiyatlandırma
A13: Ödeme | B13: 1 | C13: =Anket_Yanitlari!H4 | D13: =Anket_Yanitlari!I4 | E13: =Anket_Yanitlari!J4 | F13: =Anket_Yanitlari!K4
A14: Kullanıcı Deneyimi | B14: =1/C13 | C14: 1 | D14: =Anket_Yanitlari!L4 | E14: =Anket_Yanitlari!M4 | F14: =Anket_Yanitlari!N4
A15: Kargo | B15: =1/D13 | C15: =1/D14 | D15: 1 | E15: =Anket_Yanitlari!O4 | F15: =Anket_Yanitlari!P4
A16: Müşteri Yorumları | B16: =1/E13 | C16: =1/E14 | D16: =1/E15 | E16: 1 | F16: =Anket_Yanitlari!Q4
A17: Fiyatlandırma | B17: =1/F13 | C17: =1/F14 | D17: =1/F15 | E17: =1/F16 | F17: 1
A18: Sütun Toplamı | B18: =SUM(B13:B17) | C18: =SUM(C13:C17) | D18: =SUM(D13:D17) | E18: =SUM(E13:E17) | F18: =SUM(F13:F17)
A20: Normalize Matris (N)
B21: Ödeme | C21: Kullanıcı Deneyimi | D21: Kargo | E21: Müşteri Yorumları | F21: Fiyatlandırma
A22: Ödeme | B22: =B13/B18 | C22: =C13/C18 | D22: =D13/D18 | E22: =E13/E18 | F22: =F13/F18
A23: Kullanıcı Deneyimi | B23: =B14/B18 | C23: =C14/C18 | D23: =D14/D18 | E23: =E14/E18 | F23: =F14/F18
A24: Kargo | B24: =B15/B18 | C24: =C15/C18 | D24: =D15/D18 | E24: =E15/E18 | F24: =F15/F18
A25: Müşteri Yorumları | B25: =B16/B18 | C25: =C16/C18 | D25: =D16/D18 | E25: =E16/E18 | F25: =F16/F18
A26: Fiyatlandırma | B26: =B17/B18 | C26: =C17/C18 | D26: =D17/D18 | E26: =E17/E18 | F26: =F17/F18
A28: Kriter | B28: ÖZV (w) | C28: A·w | D28: A·w / w
A29: Ödeme | B29: =AVERAGE(B22:F22) | C29: =B13*$B$29+C13*$B$30+D13*$B$31+E13*$B$32+F13*$B$33 | D29: =C29/B29
A30: Kullanıcı Deneyimi | B30: =AVERAGE(B23:F23) | C30: =B14*$B$29+C14*$B$30+D14*$B$31+E14*$B$32+F14*$B$33 | D30: =C30/B30
A31: Kargo | B31: =AVERAGE(B24:F24) | C31: =B15*$B$29+C15*$B$30+D15*$B$31+E15*$B$32+F15*$B$33 | D31: =C31/B31
A32: Müşteri Yorumları | B32: =AVERAGE(B25:F25) | C32: =B16*$B$29+C16*$B$30+D16*$B$31+E16*$B$32+F16*$B$33 | D32: =C32/B32
A33: Fiyatlandırma | B33: =AVERAGE(B26:F26) | C33: =B17*$B$29+C17*$B$30+D17*$B$31+E17*$B$32+F17*$B$33 | D33: =C33/B33
A34: Toplam | B34: =SUM(B29:B33)
A36: λ_max (ENBÖZD) | B36: =AVERAGE(D29:D33)
A37: n (kriter sayısı) | B37: 5
A38: CI = (λ_max - n) / (n - 1) | B38: =(B36-B37)/(B37-1)
A39: RI (n=5) | B39: 1.11
A40: CR = CI / RI | B40: =B38/B39
A41: Tutarlılık Eşiği | B41: 0.1
A42: Durum | B42: =IF(B40<=B41,"Tutarlı","Tutarsız")

Sheet Katilimci 04
A1: KATILIMCI 04 - AHP ANALİZİ
A3: Demografik Bilgiler
A4: Cinsiyet | B4: =Anket_Yanitlari!B5
A5: Yaş | B5: =Anket_Yanitlari!C5
A6: Eğitim | B6: =Anket_Yanitlari!D5
A7: Meslek | B7: =Anket_Yanitlari!E5
A8: Alışveriş Sıklığı | B8: =Anket_Yanitlari!F5
A9: Cihaz | B9: =Anket_Yanitlari!G5
A11: İkili Karşılaştırma Matrisi (A)
B12: Ödeme | C12: Kullanıcı Deneyimi | D12: Kargo | E12: Müşteri Yorumları | F12: Fiyatlandırma
A13: Ödeme | B13: 1 | C13: =Anket_Yanitlari!H5 | D13: =Anket_Yanitlari!I5 | E13: =Anket_Yanitlari!J5 | F13: =Anket_Yanitlari!K5
A14: Kullanıcı Deneyimi | B14: =1/C13 | C14: 1 | D14: =Anket_Yanitlari!L5 | E14: =Anket_Yanitlari!M5 | F14: =Anket_Yanitlari!N5
A15: Kargo | B15: =1/D13 | C15: =1/D14 | D15: 1 | E15: =Anket_Yanitlari!O5 | F15: =Anket_Yanitlari!P5
A16: Müşteri Yorumları | B16: =1/E13 | C16: =1/E14 | D16: =1/E15 | E16: 1 | F16: =Anket_Yanitlari!Q5
A17: Fiyatlandırma | B17: =1/F13 | C17: =1/F14 | D17: =1/F15 | E17: =1/F16 | F17: 1
A18: Sütun Toplamı | B18: =SUM(B13:B17) | C18: =SUM(C13:C17) | D18: =SUM(D13:D17) | E18: =SUM(E13:E17) | F18: =SUM(F13:F17)
A20: Normalize Matris (N)
B21: Ödeme | C21: Kullanıcı Deneyimi | D21: Kargo | E21: Müşteri Yorumları | F21: Fiyatlandırma
A22: Ödeme | B22: =B13/B18 | C22: =C13/C18 | D22: =D13/D18 | E22: =E13/E18 | F22: =F13/F18
A23: Kullanıcı Deneyimi | B23: =B14/B18 | C23: =C14/C18 | D23: =D14/D18 | E23: =E14/E18 | F23: =F14/F18
A24: Kargo | B24: =B15/B18 | C24: =C15/C18 | D24: =D15/D18 | E24: =E15/E18 | F24: =F15/F18
A25: Müşteri Yorumları | B25: =B16/B18 | C25: =C16/C18 | D25: =D16/D18 | E25: =E16/E18 | F25: =F16/F18
A26: Fiyatlandırma | B26: =B17/B18 | C26: =C17/C18 | D26: =D17/D18 | E26: =E17/E18 | F26: =F17/F18
A28: Kriter | B28: ÖZV (w) | C28: A·w | D28: A·w / w
A29: Ödeme | B29: =AVERAGE(B22:F22) | C29: =B13*$B$29+C13*$B$30+D13*$B$31+E13*$B$32+F13*$B$33 | D29: =C29/B29
A30: Kullanıcı Deneyimi | B30: =AVERAGE(B23:F23) | C30: =B14*$B$29+C14*$B$30+D14*$B$31+E14*$B$32+F14*$B$33 | D30: =C30/B30
A31: Kargo | B31: =AVERAGE(B24:F24) | C31: =B15*$B$29+C15*$B$30+D15*$B$31+E15*$B$32+F15*$B$33 | D31: =C31/B31
A32: Müşteri Yorumları | B32: =AVERAGE(B25:F25) | C32: =B16*$B$29+C16*$B$30+D16*$B$31+E16*$B$32+F16*$B$33 | D32: =C32/B32
A33: Fiyatlandırma | B33: =AVERAGE(B26:F26) | C33: =B17*$B$29+C17*$B$30+D17*$B$31+E17*$B$32+F17*$B$33 | D33: =C33/B33
A34: Toplam | B34: =SUM(B29:B33)
A36: λ_max (ENBÖZD) | B36: =AVERAGE(D29:D33)
A37: n (kriter sayısı) | B37: 5
A38: CI = (λ_max - n) / (n - 1) | B38: =(B36-B37)/(B37-1)
A39: RI (n=5) | B39: 1.11
A40: CR = CI / RI | B40: =B38/B39
A41: Tutarlılık Eşiği | B41: 0.1
A42: Durum | B42: =IF(B40<=B41,"Tutarlı","Tutarsız")

Sheet Katilimci 05
A1: KATILIMCI 05 - AHP ANALİZİ
A3: Demografik Bilgiler
A4: Cinsiyet | B4: =Anket_Yanitlari!B6
A5: Yaş | B5: =Anket_Yanitlari!C6
A6: Eğitim | B6: =Anket_Yanitlari!D6
A7: Meslek | B7: =Anket_Yanitlari!E6
A8: Alışveriş Sıklığı | B8: =Anket_Yanitlari!F6
A9: Cihaz | B9: =Anket_Yanitlari!G6
A11: İkili Karşılaştırma Matrisi (A)
B12: Ödeme | C12: Kullanıcı Deneyimi | D12: Kargo | E12: Müşteri Yorumları | F12: Fiyatlandırma
A13: Ödeme | B13: 1 | C13: =Anket_Yanitlari!H6 | D13: =Anket_Yanitlari!I6 | E13: =Anket_Yanitlari!J6 | F13: =Anket_Yanitlari!K6
A14: Kullanıcı Deneyimi | B14: =1/C13 | C14: 1 | D14: =Anket_Yanitlari!L6 | E14: =Anket_Yanitlari!M6 | F14: =Anket_Yanitlari!N6
A15: Kargo | B15: =1/D13 | C15: =1/D14 | D15: 1 | E15: =Anket_Yanitlari!O6 | F15: =Anket_Yanitlari!P6
A16: Müşteri Yorumları | B16: =1/E13 | C16: =1/E14 | D16: =1/E15 | E16: 1 | F16: =Anket_Yanitlari!Q6
A17: Fiyatlandırma | B17: =1/F13 | C17: =1/F14 | D17: =1/F15 | E17: =1/F16 | F17: 1
A18: Sütun Toplamı | B18: =SUM(B13:B17) | C18: =SUM(C13:C17) | D18: =SUM(D13:D17) | E18: =SUM(E13:E17) | F18: =SUM(F13:F17)
A20: Normalize Matris (N)
B21: Ödeme | C21: Kullanıcı Deneyimi | D21: Kargo | E21: Müşteri Yorumları | F21: Fiyatlandırma
A22: Ödeme | B22: =B13/B18 | C22: =C13/C18 | D22: =D13/D18 | E22: =E13/E18 | F22: =F13/F18
A23: Kullanıcı Deneyimi | B23: =B14/B18 | C23: =C14/C18 | D23: =D14/D18 | E23: =E14/E18 | F23: =F14/F18
A24: Kargo | B24: =B15/B18 | C24: =C15/C18 | D24: =D15/D18 | E24: =E15/E18 | F24: =F15/F18
A25: Müşteri Yorumları | B25: =B16/B18 | C25: =C16/C18 | D25: =D16/D18 | E25: =E16/E18 | F25: =F16/F18
A26: Fiyatlandırma | B26: =B17/B18 | C26: =C17/C18 | D26: =D17/D18 | E26: =E17/E18 | F26: =F17/F18
A28: Kriter | B28: ÖZV (w) | C28: A·w | D28: A·w / w
A29: Ödeme | B29: =AVERAGE(B22:F22) | C29: =B13*$B$29+C13*$B$30+D13*$B$31+E13*$B$32+F13*$B$33 | D29: =C29/B29
A30: Kullanıcı Deneyimi | B30: =AVERAGE(B23:F23) | C30: =B14*$B$29+C14*$B$30+D14*$B$31+E14*$B$32+F14*$B$33 | D30: =C30/B30
A31: Kargo | B31: =AVERAGE(B24:F24) | C31: =B15*$B$29+C15*$B$30+D15*$B$31+E15*$B$32+F15*$B$33 | D31: =C31/B31
A32: Müşteri Yorumları | B32: =AVERAGE(B25:F25) | C32: =B16*$B$29+C16*$B$30+D16*$B$31+E16*$B$32+F16*$B$33 | D32: =C32/B32
A33: Fiyatlandırma | B33: =AVERAGE(B26:F26) | C33: =B17*$B$29+C17*$B$30+D17*$B$31+E17*$B$32+F17*$B$33 | D33: =C33/B33
A34: Toplam | B34: =SUM(B29:B33)
A36: λ_max (ENBÖZD) | B36: =AVERAGE(D29:D33)
A37: n (kriter sayısı) | B37: 5
A38: CI = (λ_max - n) / (n - 1) | B38: =(B36-B37)/(B37-1)
A39: RI (n=5) | B39: 1.11
A40: CR = CI / RI | B40: =B38/B39
A41: Tutarlılık Eşiği | B41: 0.1
A42: Durum | B42: =IF(B40<=B41,"Tutarlı","Tutarsız")

Sheet Katilimci 06
A1: KATILIMCI 06 - AHP ANALİZİ
A3: Demografik Bilgiler
A4: Cinsiyet | B4: =Anket_Yanitlari!B7
A5: Yaş | B5: =Anket_Yanitlari!C7
A6: Eğitim | B6: =Anket_Yanitlari!D7
A7: Meslek | B7: =Anket_Yanitlari!E7
A8: Alışveriş Sıklığı | B8: =Anket_Yanitlari!F7
A9: Cihaz | B9: =Anket_Yanitlari!G7
A11: İkili Karşılaştırma Matrisi (A)
B12: Ödeme | C12: Kullanıcı Deneyimi | D12: Kargo | E12: Müşteri Yorumları | F12: Fiyatlandırma
A13: Ödeme | B13: 1 | C13: =Anket_Yanitlari!H7 | D13: =Anket_Yanitlari!I7 | E13: =Anket_Yanitlari!J7 | F13: =Anket_Yanitlari!K7
A14: Kullanıcı Deneyimi | B14: =1/C13 | C14: 1 | D14: =Anket_Yanitlari!L7 | E14: =Anket_Yanitlari!M7 | F14: =Anket_Yanitlari!N7
A15: Kargo | B15: =1/D13 | C15: =1/D14 | D15: 1 | E15: =Anket_Yanitlari!O7 | F15: =Anket_Yanitlari!P7
A16: Müşteri Yorumları | B16: =1/E13 | C16: =1/E14 | D16: =1/E15 | E16: 1 | F16: =Anket_Yanitlari!Q7
A17: Fiyatlandırma | B17: =1/F13 | C17: =1/F14 | D17: =1/F15 | E17: =1/F16 | F17: 1
A18: Sütun Toplamı | B18: =SUM(B13:B17) | C18: =SUM(C13:C17) | D18: =SUM(D13:D17) | E18: =SUM(E13:E17) | F18: =SUM(F13:F17)
A20: Normalize Matris (N)
B21: Ödeme | C21: Kullanıcı Deneyimi | D21: Kargo | E21: Müşteri Yorumları | F21: Fiyatlandırma
A22: Ödeme | B22: =B13/B18 | C22: =C13/C18 | D22: =D13/D18 | E22: =E13/E18 | F22: =F13/F18
A23: Kullanıcı Deneyimi | B23: =B14/B18 | C23: =C14/C18 | D23: =D14/D18 | E23: =E14/E18 | F23: =F14/F18
A24: Kargo | B24: =B15/B18 | C24: =C15/C18 | D24: =D15/D18 | E24: =E15/E18 | F24: =F15/F18
A25: Müşteri Yorumları | B25: =B16/B18 | C25: =C16/C18 | D25: =D16/D18 | E25: =E16/E18 | F25: =F16/F18
A26: Fiyatlandırma | B26: =B17/B18 | C26: =C17/C18 | D26: =D17/D18 | E26: =E17/E18 | F26: =F17/F18
A28: Kriter | B28: ÖZV (w) | C28: A·w | D28: A·w / w
A29: Ödeme | B29: =AVERAGE(B22:F22) | C29: =B13*$B$29+C13*$B$30+D13*$B$31+E13*$B$32+F13*$B$33 | D29: =C29/B29
A30: Kullanıcı Deneyimi | B30: =AVERAGE(B23:F23) | C30: =B14*$B$29+C14*$B$30+D14*$B$31+E14*$B$32+F14*$B$33 | D30: =C30/B30
A31: Kargo | B31: =AVERAGE(B24:F24) | C31: =B15*$B$29+C15*$B$30+D15*$B$31+E15*$B$32+F15*$B$33 | D31: =C31/B31
A32: Müşteri Yorumları | B32: =AVERAGE(B25:F25) | C32: =B16*$B$29+C16*$B$30+D16*$B$31+E16*$B$32+F16*$B$33 | D32: =C32/B32
A33: Fiyatlandırma | B33: =AVERAGE(B26:F26) | C33: =B17*$B$29+C17*$B$30+D17*$B$31+E17*$B$32+F17*$B$33 | D33: =C33/B33
A34: Toplam | B34: =SUM(B29:B33)
A36: λ_max (ENBÖZD) | B36: =AVERAGE(D29:D33)
A37: n (kriter sayısı) | B37: 5
A38: CI = (λ_max - n) / (n - 1) | B38: =(B36-B37)/(B37-1)
A39: RI (n=5) | B39: 1.11
A40: CR = CI / RI | B40: =B38/B39
A41: Tutarlılık Eşiği | B41: 0.1
A42: Durum | B42: =IF(B40<=B41,"Tutarlı","Tutarsız")

Sheet Katilimci 07
A1: KATILIMCI 07 - AHP ANALİZİ
A3: Demografik Bilgiler
A4: Cinsiyet | B4: =Anket_Yanitlari!B8
A5: Yaş | B5: =Anket_Yanitlari!C8
A6: Eğitim | B6: =Anket_Yanitlari!D8
A7: Meslek | B7: =Anket_Yanitlari!E8
A8: Alışveriş Sıklığı | B8: =Anket_Yanitlari!F8
A9: Cihaz | B9: =Anket_Yanitlari!G8
A11: İkili Karşılaştırma Matrisi (A)
B12: Ödeme | C12: Kullanıcı Deneyimi | D12: Kargo | E12: Müşteri Yorumları | F12: Fiyatlandırma
A13: Ödeme | B13: 1 | C13: =Anket_Yanitlari!H8 | D13: =Anket_Yanitlari!I8 | E13: =Anket_Yanitlari!J8 | F13: =Anket_Yanitlari!K8
A14: Kullanıcı Deneyimi | B14: =1/C13 | C14: 1 | D14: =Anket_Yanitlari!L8 | E14: =Anket_Yanitlari!M8 | F14: =Anket_Yanitlari!N8
A15: Kargo | B15: =1/D13 | C15: =1/D14 | D15: 1 | E15: =Anket_Yanitlari!O8 | F15: =Anket_Yanitlari!P8
A16: Müşteri Yorumları | B16: =1/E13 | C16: =1/E14 | D16: =1/E15 | E16: 1 | F16: =Anket_Yanitlari!Q8
A17: Fiyatlandırma | B17: =1/F13 | C17: =1/F14 | D17: =1/F15 | E17: =1/F16 | F17: 1
A18: Sütun Toplamı | B18: =SUM(B13:B17) | C18: =SUM(C13:C17) | D18: =SUM(D13:D17) | E18: =SUM(E13:E17) | F18: =SUM(F13:F17)
A20: Normalize Matris (N)
B21: Ödeme | C21: Kullanıcı Deneyimi | D21: Kargo | E21: Müşteri Yorumları | F21: Fiyatlandırma
A22: Ödeme | B22: =B13/B18 | C22: =C13/C18 | D22: =D13/D18 | E22: =E13/E18 | F22: =F13/F18
A23: Kullanıcı Deneyimi | B23: =B14/B18 | C23: =C14/C18 | D23: =D14/D18 | E23: =E14/E18 | F23: =F14/F18
A24: Kargo | B24: =B15/B18 | C24: =C15/C18 | D24: =D15/D18 | E24: =E15/E18 | F24: =F15/F18
A25: Müşteri Yorumları | B25: =B16/B18 | C25: =C16/C18 | D25: =D16/D18 | E25: =E16/E18 | F25: =F16/F18
A26: Fiyatlandırma | B26: =B17/B18 | C26: =C17/C18 | D26: =D17/D18 | E26: =E17/E18 | F26: =F17/F18
A28: Kriter | B28: ÖZV (w) | C28: A·w | D28: A·w / w
A29: Ödeme | B29: =AVERAGE(B22:F22) | C29: =B13*$B$29+C13*$B$30+D13*$B$31+E13*$B$32+F13*$B$33 | D29: =C29/B29
A30: Kullanıcı Deneyimi | B30: =AVERAGE(B23:F23) | C30: =B14*$B$29+C14*$B$30+D14*$B$31+E14*$B$32+F14*$B$33 | D30: =C30/B30
A31: Kargo | B31: =AVERAGE(B24:F24) | C31: =B15*$B$29+C15*$B$30+D15*$B$31+E15*$B$32+F15*$B$33 | D31: =C31/B31
A32: Müşteri Yorumları | B32: =AVERAGE(B25:F25) | C32: =B16*$B$29+C16*$B$30+D16*$B$31+E16*$B$32+F16*$B$33 | D32: =C32/B32
A33: Fiyatlandırma | B33: =AVERAGE(B26:F26) | C33: =B17*$B$29+C17*$B$30+D17*$B$31+E17*$B$32+F17*$B$33 | D33: =C33/B33
A34: Toplam | B34: =SUM(B29:B33)
A36: λ_max (ENBÖZD) | B36: =AVERAGE(D29:D33)
A37: n (kriter sayısı) | B37: 5
A38: CI = (λ_max - n) / (n - 1) | B38: =(B36-B37)/(B37-1)
A39: RI (n=5) | B39: 1.11
A40: CR = CI / RI | B40: =B38/B39
A41: Tutarlılık Eşiği | B41: 0.1
A42: Durum | B42: =IF(B40<=B41,"Tutarlı","Tutarsız")

Sheet Katilimci 08
A1: KATILIMCI 08 - AHP ANALİZİ
A3: Demografik Bilgiler
A4: Cinsiyet | B4: =Anket_Yanitlari!B9
A5: Yaş | B5: =Anket_Yanitlari!C9
A6: Eğitim | B6: =Anket_Yanitlari!D9
A7: Meslek | B7: =Anket_Yanitlari!E9
A8: Alışveriş Sıklığı | B8: =Anket_Yanitlari!F9
A9: Cihaz | B9: =Anket_Yanitlari!G9
A11: İkili Karşılaştırma Matrisi (A)
B12: Ödeme | C12: Kullanıcı Deneyimi | D12: Kargo | E12: Müşteri Yorumları | F12: Fiyatlandırma
A13: Ödeme | B13: 1 | C13: =Anket_Yanitlari!H9 | D13: =Anket_Yanitlari!I9 | E13: =Anket_Yanitlari!J9 | F13: =Anket_Yanitlari!K9
A14: Kullanıcı Deneyimi | B14: =1/C13 | C14: 1 | D14: =Anket_Yanitlari!L9 | E14: =Anket_Yanitlari!M9 | F14: =Anket_Yanitlari!N9
A15: Kargo | B15: =1/D13 | C15: =1/D14 | D15: 1 | E15: =Anket_Yanitlari!O9 | F15: =Anket_Yanitlari!P9
A16: Müşteri Yorumları | B16: =1/E13 | C16: =1/E14 | D16: =1/E15 | E16: 1 | F16: =Anket_Yanitlari!Q9
A17: Fiyatlandırma | B17: =1/F13 | C17: =1/F14 | D17: =1/F15 | E17: =1/F16 | F17: 1
A18: Sütun Toplamı | B18: =SUM(B13:B17) | C18: =SUM(C13:C17) | D18: =SUM(D13:D17) | E18: =SUM(E13:E17) | F18: =SUM(F13:F17)
A20: Normalize Matris (N)
B21: Ödeme | C21: Kullanıcı Deneyimi | D21: Kargo | E21: Müşteri Yorumları | F21: Fiyatlandırma
A22: Ödeme | B22: =B13/B18 | C22: =C13/C18 | D22: =D13/D18 | E22: =E13/E18 | F22: =F13/F18
A23: Kullanıcı Deneyimi | B23: =B14/B18 | C23: =C14/C18 | D23: =D14/D18 | E23: =E14/E18 | F23: =F14/F18
A24: Kargo | B24: =B15/B18 | C24: =C15/C18 | D24: =D15/D18 | E24: =E15/E18 | F24: =F15/F18
A25: Müşteri Yorumları | B25: =B16/B18 | C25: =C16/C18 | D25: =D16/D18 | E25: =E16/E18 | F25: =F16/F18
A26: Fiyatlandırma | B26: =B17/B18 | C26: =C17/C18 | D26: =D17/D18 | E26: =E17/E18 | F26: =F17/F18
A28: Kriter | B28: ÖZV (w) | C28: A·w | D28: A·w / w
A29: Ödeme | B29: =AVERAGE(B22:F22) | C29: =B13*$B$29+C13*$B$30+D13*$B$31+E13*$B$32+F13*$B$33 | D29: =C29/B29
A30: Kullanıcı Deneyimi | B30: =AVERAGE(B23:F23) | C30: =B14*$B$29+C14*$B$30+D14*$B$31+E14*$B$32+F14*$B$33 | D30: =C30/B30
A31: Kargo | B31: =AVERAGE(B24:F24) | C31: =B15*$B$29+C15*$B$30+D15*$B$31+E15*$B$32+F15*$B$33 | D31: =C31/B31
A32: Müşteri Yorumları | B32: =AVERAGE(B25:F25) | C32: =B16*$B$29+C16*$B$30+D16*$B$31+E16*$B$32+F16*$B$33 | D32: =C32/B32
A33: Fiyatlandırma | B33: =AVERAGE(B26:F26) | C33: =B17*$B$29+C17*$B$30+D17*$B$31+E17*$B$32+F17*$B$33 | D33: =C33/B33
A34: Toplam | B34: =SUM(B29:B33)
A36: λ_max (ENBÖZD) | B36: =AVERAGE(D29:D33)
A37: n (kriter sayısı) | B37: 5
A38: CI = (λ_max - n) / (n - 1) | B38: =(B36-B37)/(B37-1)
A39: RI (n=5) | B39: 1.11
A40: CR = CI / RI | B40: =B38/B39
A41: Tutarlılık Eşiği | B41: 0.1
A42: Durum | B42: =IF(B40<=B41,"Tutarlı","Tutarsız")

Sheet Katilimci 09
A1: KATILIMCI 09 - AHP ANALİZİ
A3: Demografik Bilgiler
A4: Cinsiyet | B4: =Anket_Yanitlari!B10
A5: Yaş | B5: =Anket_Yanitlari!C10
A6: Eğitim | B6: =Anket_Yanitlari!D10
A7: Meslek | B7: =Anket_Yanitlari!E10
A8: Alışveriş Sıklığı | B8: =Anket_Yanitlari!F10
A9: Cihaz | B9: =Anket_Yanitlari!G10
A11: İkili Karşılaştırma Matrisi (A)
B12: Ödeme | C12: Kullanıcı Deneyimi | D12: Kargo | E12: Müşteri Yorumları | F12: Fiyatlandırma
A13: Ödeme | B13: 1 | C13: =Anket_Yanitlari!H10 | D13: =Anket_Yanitlari!I10 | E13: =Anket_Yanitlari!J10 | F13: =Anket_Yanitlari!K10
A14: Kullanıcı Deneyimi | B14: =1/C13 | C14: 1 | D14: =Anket_Yanitlari!L10 | E14: =Anket_Yanitlari!M10 | F14: =Anket_Yanitlari!N10
A15: Kargo | B15: =1/D13 | C15: =1/D14 | D15: 1 | E15: =Anket_Yanitlari!O10 | F15: =Anket_Yanitlari!P10
A16: Müşteri Yorumları | B16: =1/E13 | C16: =1/E14 | D16: =1/E15 | E16: 1 | F16: =Anket_Yanitlari!Q10
A17: Fiyatlandırma | B17: =1/F13 | C17: =1/F14 | D17: =1/F15 | E17: =1/F16 | F17: 1
A18: Sütun Toplamı | B18: =SUM(B13:B17) | C18: =SUM(C13:C17) | D18: =SUM(D13:D17) | E18: =SUM(E13:E17) | F18: =SUM(F13:F17)
A20: Normalize Matris (N)
B21: Ödeme | C21: Kullanıcı Deneyimi | D21: Kargo | E21: Müşteri Yorumları | F21: Fiyatlandırma
A22: Ödeme | B22: =B13/B18 | C22: =C13/C18 | D22: =D13/D18 | E22: =E13/E18 | F22: =F13/F18
A23: Kullanıcı Deneyimi | B23: =B14/B18 | C23: =C14/C18 | D23: =D14/D18 | E23: =E14/E18 | F23: =F14/F18
A24: Kargo | B24: =B15/B18 | C24: =C15/C18 | D24: =D15/D18 | E24: =E15/E18 | F24: =F15/F18
A25: Müşteri Yorumları | B25: =B16/B18 | C25: =C16/C18 | D25: =D16/D18 | E25: =E16/E18 | F25: =F16/F18
A26: Fiyatlandırma | B26: =B17/B18 | C26: =C17/C18 | D26: =D17/D18 | E26: =E17/E18 | F26: =F17/F18
A28: Kriter | B28: ÖZV (w) | C28: A·w | D28: A·w / w
A29: Ödeme | B29: =AVERAGE(B22:F22) | C29: =B13*$B$29+C13*$B$30+D13*$B$31+E13*$B$32+F13*$B$33 | D29: =C29/B29
A30: Kullanıcı Deneyimi | B30: =AVERAGE(B23:F23) | C30: =B14*$B$29+C14*$B$30+D14*$B$31+E14*$B$32+F14*$B$33 | D30: =C30/B30
A31: Kargo | B31: =AVERAGE(B24:F24) | C31: =B15*$B$29+C15*$B$30+D15*$B$31+E15*$B$32+F15*$B$33 | D31: =C31/B31
A32: Müşteri Yorumları | B32: =AVERAGE(B25:F25) | C32: =B16*$B$29+C16*$B$30+D16*$B$31+E16*$B$32+F16*$B$33 | D32: =C32/B32
A33: Fiyatlandırma | B33: =AVERAGE(B26:F26) | C33: =B17*$B$29+C17*$B$30+D17*$B$31+E17*$B$32+F17*$B$33 | D33: =C33/B33
A34: Toplam | B34: =SUM(B29:B33)
A36: λ_max (ENBÖZD) | B36: =AVERAGE(D29:D33)
A37: n (kriter sayısı) | B37: 5
A38: CI = (λ_max - n) / (n - 1) | B38: =(B36-B37)/(B37-1)
A39: RI (n=5) | B39: 1.11
A40: CR = CI / RI | B40: =B38/B39
A41: Tutarlılık Eşiği | B41: 0.1
A42: Durum | B42: =IF(B40<=B41,"Tutarlı","Tutarsız")

Sheet Katilimci 10
A1: KATILIMCI 10 - AHP ANALİZİ
A3: Demografik Bilgiler
A4: Cinsiyet | B4: =Anket_Yanitlari!B11
A5: Yaş | B5: =Anket_Yanitlari!C11
A6: Eğitim | B6: =Anket_Yanitlari!D11
A7: Meslek | B7: =Anket_Yanitlari!E11
A8: Alışveriş Sıklığı | B8: =Anket_Yanitlari!F11
A9: Cihaz | B9: =Anket_Yanitlari!G11
A11: İkili Karşılaştırma Matrisi (A)
B12: Ödeme | C12: Kullanıcı Deneyimi | D12: Kargo | E12: Müşteri Yorumları | F12: Fiyatlandırma
A13: Ödeme | B13: 1 | C13: =Anket_Yanitlari!H11 | D13: =Anket_Yanitlari!I11 | E13: =Anket_Yanitlari!J11 | F13: =Anket_Yanitlari!K11
A14: Kullanıcı Deneyimi | B14: =1/C13 | C14: 1 | D14: =Anket_Yanitlari!L11 | E14: =Anket_Yanitlari!M11 | F14: =Anket_Yanitlari!N11
A15: Kargo | B15: =1/D13 | C15: =1/D14 | D15: 1 | E15: =Anket_Yanitlari!O11 | F15: =Anket_Yanitlari!P11
A16: Müşteri Yorumları | B16: =1/E13 | C16: =1/E14 | D16: =1/E15 | E16: 1 | F16: =Anket_Yanitlari!Q11
A17: Fiyatlandırma | B17: =1/F13 | C17: =1/F14 | D17: =1/F15 | E17: =1/F16 | F17: 1
A18: Sütun Toplamı | B18: =SUM(B13:B17) | C18: =SUM(C13:C17) | D18: =SUM(D13:D17) | E18: =SUM(E13:E17) | F18: =SUM(F13:F17)
A20: Normalize Matris (N)
B21: Ödeme | C21: Kullanıcı Deneyimi | D21: Kargo | E21: Müşteri Yorumları | F21: Fiyatlandırma
A22: Ödeme | B22: =B13/B18 | C22: =C13/C18 | D22: =D13/D18 | E22: =E13/E18 | F22: =F13/F18
A23: Kullanıcı Deneyimi | B23: =B14/B18 | C23: =C14/C18 | D23: =D14/D18 | E23: =E14/E18 | F23: =F14/F18
A24: Kargo | B24: =B15/B18 | C24: =C15/C18 | D24: =D15/D18 | E24: =E15/E18 | F24: =F15/F18
A25: Müşteri Yorumları | B25: =B16/B18 | C25: =C16/C18 | D25: =D16/D18 | E25: =E16/E18 | F25: =F16/F18
A26: Fiyatlandırma | B26: =B17/B18 | C26: =C17/C18 | D26: =D17/D18 | E26: =E17/E18 | F26: =F17/F18
A28: Kriter | B28: ÖZV (w) | C28: A·w | D28: A·w / w
A29: Ödeme | B29: =AVERAGE(B22:F22) | C29: =B13*$B$29+C13*$B$30+D13*$B$31+E13*$B$32+F13*$B$33 | D29: =C29/B29
A30: Kullanıcı Deneyimi | B30: =AVERAGE(B23:F23) | C30: =B14*$B$29+C14*$B$30+D14*$B$31+E14*$B$32+F14*$B$33 | D30: =C30/B30
A31: Kargo | B31: =AVERAGE(B24:F24) | C31: =B15*$B$29+C15*$B$30+D15*$B$31+E15*$B$32+F15*$B$33 | D31: =C31/B31
A32: Müşteri Yorumları | B32: =AVERAGE(B25:F25) | C32: =B16*$B$29+C16*$B$30+D16*$B$31+E16*$B$32+F16*$B$33 | D32: =C32/B32
A33: Fiyatlandırma | B33: =AVERAGE(B26:F26) | C33: =B17*$B$29+C17*$B$30+D17*$B$31+E17*$B$32+F17*$B$33 | D33: =C33/B33
A34: Toplam | B34: =SUM(B29:B33)
A36: λ_max (ENBÖZD) | B36: =AVERAGE(D29:D33)
A37: n (kriter sayısı) | B37: 5
A38: CI = (λ_max - n) / (n - 1) | B38: =(B36-B37)/(B37-1)
A39: RI (n=5) | B39: 1.11
A40: CR = CI / RI | B40: =B38/B39
A41: Tutarlılık Eşiği | B41: 0.1
A42: Durum | B42: =IF(B40<=B41,"Tutarlı","Tutarsız")

Sheet Katilimci 11
A1: KATILIMCI 11 - AHP ANALİZİ
A3: Demografik Bilgiler
A4: Cinsiyet | B4: =Anket_Yanitlari!B12
A5: Yaş | B5: =Anket_Yanitlari!C12
A6: Eğitim | B6: =Anket_Yanitlari!D12
A7: Meslek | B7: =Anket_Yanitlari!E12
A8: Alışveriş Sıklığı | B8: =Anket_Yanitlari!F12
A9: Cihaz | B9: =Anket_Yanitlari!G12
A11: İkili Karşılaştırma Matrisi (A)
B12: Ödeme | C12: Kullanıcı Deneyimi | D12: Kargo | E12: Müşteri Yorumları | F12: Fiyatlandırma
A13: Ödeme | B13: 1 | C13: =Anket_Yanitlari!H12 | D13: =Anket_Yanitlari!I12 | E13: =Anket_Yanitlari!J12 | F13: =Anket_Yanitlari!K12
A14: Kullanıcı Deneyimi | B14: =1/C13 | C14: 1 | D14: =Anket_Yanitlari!L12 | E14: =Anket_Yanitlari!M12 | F14: =Anket_Yanitlari!N12
A15: Kargo | B15: =1/D13 | C15: =1/D14 | D15: 1 | E15: =Anket_Yanitlari!O12 | F15: =Anket_Yanitlari!P12
A16: Müşteri Yorumları | B16: =1/E13 | C16: =1/E14 | D16: =1/E15 | E16: 1 | F16: =Anket_Yanitlari!Q12
A17: Fiyatlandırma | B17: =1/F13 | C17: =1/F14 | D17: =1/F15 | E17: =1/F16 | F17: 1
A18: Sütun Toplamı | B18: =SUM(B13:B17) | C18: =SUM(C13:C17) | D18: =SUM(D13:D17) | E18: =SUM(E13:E17) | F18: =SUM(F13:F17)
A20: Normalize Matris (N)
B21: Ödeme | C21: Kullanıcı Deneyimi | D21: Kargo | E21: Müşteri Yorumları | F21: Fiyatlandırma
A22: Ödeme | B22: =B13/B18 | C22: =C13/C18 | D22: =D13/D18 | E22: =E13/E18 | F22: =F13/F18
A23: Kullanıcı Deneyimi | B23: =B14/B18 | C23: =C14/C18 | D23: =D14/D18 | E23: =E14/E18 | F23: =F14/F18
A24: Kargo | B24: =B15/B18 | C24: =C15/C18 | D24: =D15/D18 | E24: =E15/E18 | F24: =F15/F18
A25: Müşteri Yorumları | B25: =B16/B18 | C25: =C16/C18 | D25: =D16/D18 | E25: =E16/E18 | F25: =F16/F18
A26: Fiyatlandırma | B26: =B17/B18 | C26: =C17/C18 | D26: =D17/D18 | E26: =E17/E18 | F26: =F17/F18
A28: Kriter | B28: ÖZV (w) | C28: A·w | D28: A·w / w
A29: Ödeme | B29: =AVERAGE(B22:F22) | C29: =B13*$B$29+C13*$B$30+D13*$B$31+E13*$B$32+F13*$B$33 | D29: =C29/B29
A30: Kullanıcı Deneyimi | B30: =AVERAGE(B23:F23) | C30: =B14*$B$29+C14*$B$30+D14*$B$31+E14*$B$32+F14*$B$33 | D30: =C30/B30
A31: Kargo | B31: =AVERAGE(B24:F24) | C31: =B15*$B$29+C15*$B$30+D15*$B$31+E15*$B$32+F15*$B$33 | D31: =C31/B31
A32: Müşteri Yorumları | B32: =AVERAGE(B25:F25) | C32: =B16*$B$29+C16*$B$30+D16*$B$31+E16*$B$32+F16*$B$33 | D32: =C32/B32
A33: Fiyatlandırma | B33: =AVERAGE(B26:F26) | C33: =B17*$B$29+C17*$B$30+D17*$B$31+E17*$B$32+F17*$B$33 | D33: =C33/B33
A34: Toplam | B34: =SUM(B29:B33)
A36: λ_max (ENBÖZD) | B36: =AVERAGE(D29:D33)
A37: n (kriter sayısı) | B37: 5
A38: CI = (λ_max - n) / (n - 1) | B38: =(B36-B37)/(B37-1)
A39: RI (n=5) | B39: 1.11
A40: CR = CI / RI | B40: =B38/B39
A41: Tutarlılık Eşiği | B41: 0.1
A42: Durum | B42: =IF(B40<=B41,"Tutarlı","Tutarsız")

Sheet Katilimci 12
A1: KATILIMCI 12 - AHP ANALİZİ
A3: Demografik Bilgiler
A4: Cinsiyet | B4: =Anket_Yanitlari!B13
A5: Yaş | B5: =Anket_Yanitlari!C13
A6: Eğitim | B6: =Anket_Yanitlari!D13
A7: Meslek | B7: =Anket_Yanitlari!E13
A8: Alışveriş Sıklığı | B8: =Anket_Yanitlari!F13
A9: Cihaz | B9: =Anket_Yanitlari!G13
A11: İkili Karşılaştırma Matrisi (A)
B12: Ödeme | C12: Kullanıcı Deneyimi | D12: Kargo | E12: Müşteri Yorumları | F12: Fiyatlandırma
A13: Ödeme | B13: 1 | C13: =Anket_Yanitlari!H13 | D13: =Anket_Yanitlari!I13 | E13: =Anket_Yanitlari!J13 | F13: =Anket_Yanitlari!K13
A14: Kullanıcı Deneyimi | B14: =1/C13 | C14: 1 | D14: =Anket_Yanitlari!L13 | E14: =Anket_Yanitlari!M13 | F14: =Anket_Yanitlari!N13
A15: Kargo | B15: =1/D13 | C15: =1/D14 | D15: 1 | E15: =Anket_Yanitlari!O13 | F15: =Anket_Yanitlari!P13
A16: Müşteri Yorumları | B16: =1/E13 | C16: =1/E14 | D16: =1/E15 | E16: 1 | F16: =Anket_Yanitlari!Q13
A17: Fiyatlandırma | B17: =1/F13 | C17: =1/F14 | D17: =1/F15 | E17: =1/F16 | F17: 1
A18: Sütun Toplamı | B18: =SUM(B13:B17) | C18: =SUM(C13:C17) | D18: =SUM(D13:D17) | E18: =SUM(E13:E17) | F18: =SUM(F13:F17)
A20: Normalize Matris (N)
B21: Ödeme | C21: Kullanıcı Deneyimi | D21: Kargo | E21: Müşteri Yorumları | F21: Fiyatlandırma
A22: Ödeme | B22: =B13/B18 | C22: =C13/C18 | D22: =D13/D18 | E22: =E13/E18 | F22: =F13/F18
A23: Kullanıcı Deneyimi | B23: =B14/B18 | C23: =C14/C18 | D23: =D14/D18 | E23: =E14/E18 | F23: =F14/F18
A24: Kargo | B24: =B15/B18 | C24: =C15/C18 | D24: =D15/D18 | E24: =E15/E18 | F24: =F15/F18
A25: Müşteri Yorumları | B25: =B16/B18 | C25: =C16/C18 | D25: =D16/D18 | E25: =E16/E18 | F25: =F16/F18
A26: Fiyatlandırma | B26: =B17/B18 | C26: =C17/C18 | D26: =D17/D18 | E26: =E17/E18 | F26: =F17/F18
A28: Kriter | B28: ÖZV (w) | C28: A·w | D28: A·w / w
A29: Ödeme | B29: =AVERAGE(B22:F22) | C29: =B13*$B$29+C13*$B$30+D13*$B$31+E13*$B$32+F13*$B$33 | D29: =C29/B29
A30: Kullanıcı Deneyimi | B30: =AVERAGE(B23:F23) | C30: =B14*$B$29+C14*$B$30+D14*$B$31+E14*$B$32+F14*$B$33 | D30: =C30/B30
A31: Kargo | B31: =AVERAGE(B24:F24) | C31: =B15*$B$29+C15*$B$30+D15*$B$31+E15*$B$32+F15*$B$33 | D31: =C31/B31
A32: Müşteri Yorumları | B32: =AVERAGE(B25:F25) | C32: =B16*$B$29+C16*$B$30+D16*$B$31+E16*$B$32+F16*$B$33 | D32: =C32/B32
A33: Fiyatlandırma | B33: =AVERAGE(B26:F26) | C33: =B17*$B$29+C17*$B$30+D17*$B$31+E17*$B$32+F17*$B$33 | D33: =C33/B33
A34: Toplam | B34: =SUM(B29:B33)
A36: λ_max (ENBÖZD) | B36: =AVERAGE(D29:D33)
A37: n (kriter sayısı) | B37: 5
A38: CI = (λ_max - n) / (n - 1) | B38: =(B36-B37)/(B37-1)
A39: RI (n=5) | B39: 1.11
A40: CR = CI / RI | B40: =B38/B39
A41: Tutarlılık Eşiği | B41: 0.1
A42: Durum | B42: =IF(B40<=B41,"Tutarlı","Tutarsız")

Sheet Katilimci 13
A1: KATILIMCI 13 - AHP ANALİZİ
A3: Demografik Bilgiler
A4: Cinsiyet | B4: =Anket_Yanitlari!B14
A5: Yaş | B5: =Anket_Yanitlari!C14
A6: Eğitim | B6: =Anket_Yanitlari!D14
A7: Meslek | B7: =Anket_Yanitlari!E14
A8: Alışveriş Sıklığı | B8: =Anket_Yanitlari!F14
A9: Cihaz | B9: =Anket_Yanitlari!G14
A11: İkili Karşılaştırma Matrisi (A)
B12: Ödeme | C12: Kullanıcı Deneyimi | D12: Kargo | E12: Müşteri Yorumları | F12: Fiyatlandırma
A13: Ödeme | B13: 1 | C13: =Anket_Yanitlari!H14 | D13: =Anket_Yanitlari!I14 | E13: =Anket_Yanitlari!J14 | F13: =Anket_Yanitlari!K14
A14: Kullanıcı Deneyimi | B14: =1/C13 | C14: 1 | D14: =Anket_Yanitlari!L14 | E14: =Anket_Yanitlari!M14 | F14: =Anket_Yanitlari!N14
A15: Kargo | B15: =1/D13 | C15: =1/D14 | D15: 1 | E15: =Anket_Yanitlari!O14 | F15: =Anket_Yanitlari!P14
A16: Müşteri Yorumları | B16: =1/E13 | C16: =1/E14 | D16: =1/E15 | E16: 1 | F16: =Anket_Yanitlari!Q14
A17: Fiyatlandırma | B17: =1/F13 | C17: =1/F14 | D17: =1/F15 | E17: =1/F16 | F17: 1
A18: Sütun Toplamı | B18: =SUM(B13:B17) | C18: =SUM(C13:C17) | D18: =SUM(D13:D17) | E18: =SUM(E13:E17) | F18: =SUM(F13:F17)
A20: Normalize Matris (N)
B21: Ödeme | C21: Kullanıcı Deneyimi | D21: Kargo | E21: Müşteri Yorumları | F21: Fiyatlandırma
A22: Ödeme | B22: =B13/B18 | C22: =C13/C18 | D22: =D13/D18 | E22: =E13/E18 | F22: =F13/F18
A23: Kullanıcı Deneyimi | B23: =B14/B18 | C23: =C14/C18 | D23: =D14/D18 | E23: =E14/E18 | F23: =F14/F18
A24: Kargo | B24: =B15/B18 | C24: =C15/C18 | D24: =D15/D18 | E24: =E15/E18 | F24: =F15/F18
A25: Müşteri Yorumları | B25: =B16/B18 | C25: =C16/C18 | D25: =D16/D18 | E25: =E16/E18 | F25: =F16/F18
A26: Fiyatlandırma | B26: =B17/B18 | C26: =C17/C18 | D26: =D17/D18 | E26: =E17/E18 | F26: =F17/F18
A28: Kriter | B28: ÖZV (w) | C28: A·w | D28: A·w / w
A29: Ödeme | B29: =AVERAGE(B22:F22) | C29: =B13*$B$29+C13*$B$30+D13*$B$31+E13*$B$32+F13*$B$33 | D29: =C29/B29
A30: Kullanıcı Deneyimi | B30: =AVERAGE(B23:F23) | C30: =B14*$B$29+C14*$B$30+D14*$B$31+E14*$B$32+F14*$B$33 | D30: =C30/B30
A31: Kargo | B31: =AVERAGE(B24:F24) | C31: =B15*$B$29+C15*$B$30+D15*$B$31+E15*$B$32+F15*$B$33 | D31: =C31/B31
A32: Müşteri Yorumları | B32: =AVERAGE(B25:F25) | C32: =B16*$B$29+C16*$B$30+D16*$B$31+E16*$B$32+F16*$B$33 | D32: =C32/B32
A33: Fiyatlandırma | B33: =AVERAGE(B26:F26) | C33: =B17*$B$29+C17*$B$30+D17*$B$31+E17*$B$32+F17*$B$33 | D33: =C33/B33
A34: Toplam | B34: =SUM(B29:B33)
A36: λ_max (ENBÖZD) | B36: =AVERAGE(D29:D33)
A37: n (kriter sayısı) | B37: 5
A38: CI = (λ_max - n) / (n - 1) | B38: =(B36-B37)/(B37-1)
A39: RI (n=5) | B39: 1.11
A40: CR = CI / RI | B40: =B38/B39
A41: Tutarlılık Eşiği | B41: 0.1
A42: Durum | B42: =IF(B40<=B41,"Tutarlı","Tutarsız")

Sheet Katilimci 14
A1: KATILIMCI 14 - AHP ANALİZİ
A3: Demografik Bilgiler
A4: Cinsiyet | B4: =Anket_Yanitlari!B15
A5: Yaş | B5: =Anket_Yanitlari!C15
A6: Eğitim | B6: =Anket_Yanitlari!D15
A7: Meslek | B7: =Anket_Yanitlari!E15
A8: Alışveriş Sıklığı | B8: =Anket_Yanitlari!F15
A9: Cihaz | B9: =Anket_Yanitlari!G15
A11: İkili Karşılaştırma Matrisi (A)
B12: Ödeme | C12: Kullanıcı Deneyimi | D12: Kargo | E12: Müşteri Yorumları | F12: Fiyatlandırma
A13: Ödeme | B13: 1 | C13: =Anket_Yanitlari!H15 | D13: =Anket_Yanitlari!I15 | E13: =Anket_Yanitlari!J15 | F13: =Anket_Yanitlari!K15
A14: Kullanıcı Deneyimi | B14: =1/C13 | C14: 1 | D14: =Anket_Yanitlari!L15 | E14: =Anket_Yanitlari!M15 | F14: =Anket_Yanitlari!N15
A15: Kargo | B15: =1/D13 | C15: =1/D14 | D15: 1 | E15: =Anket_Yanitlari!O15 | F15: =Anket_Yanitlari!P15
A16: Müşteri Yorumları | B16: =1/E13 | C16: =1/E14 | D16: =1/E15 | E16: 1 | F16: =Anket_Yanitlari!Q15
A17: Fiyatlandırma | B17: =1/F13 | C17: =1/F14 | D17: =1/F15 | E17: =1/F16 | F17: 1
A18: Sütun Toplamı | B18: =SUM(B13:B17) | C18: =SUM(C13:C17) | D18: =SUM(D13:D17) | E18: =SUM(E13:E17) | F18: =SUM(F13:F17)
A20: Normalize Matris (N)
B21: Ödeme | C21: Kullanıcı Deneyimi | D21: Kargo | E21: Müşteri Yorumları | F21: Fiyatlandırma
A22: Ödeme | B22: =B13/B18 | C22: =C13/C18 | D22: =D13/D18 | E22: =E13/E18 | F22: =F13/F18
A23: Kullanıcı Deneyimi | B23: =B14/B18 | C23: =C14/C18 | D23: =D14/D18 | E23: =E14/E18 | F23: =F14/F18
A24: Kargo | B24: =B15/B18 | C24: =C15/C18 | D24: =D15/D18 | E24: =E15/E18 | F24: =F15/F18
A25: Müşteri Yorumları | B25: =B16/B18 | C25: =C16/C18 | D25: =D16/D18 | E25: =E16/E18 | F25: =F16/F18
A26: Fiyatlandırma | B26: =B17/B18 | C26: =C17/C18 | D26: =D17/D18 | E26: =E17/E18 | F26: =F17/F18
A28: Kriter | B28: ÖZV (w) | C28: A·w | D28: A·w / w
A29: Ödeme | B29: =AVERAGE(B22:F22) | C29: =B13*$B$29+C13*$B$30+D13*$B$31+E13*$B$32+F13*$B$33 | D29: =C29/B29
A30: Kullanıcı Deneyimi | B30: =AVERAGE(B23:F23) | C30: =B14*$B$29+C14*$B$30+D14*$B$31+E14*$B$32+F14*$B$33 | D30: =C30/B30
A31: Kargo | B31: =AVERAGE(B24:F24) | C31: =B15*$B$29+C15*$B$30+D15*$B$31+E15*$B$32+F15*$B$33 | D31: =C31/B31
A32: Müşteri Yorumları | B32: =AVERAGE(B25:F25) | C32: =B16*$B$29+C16*$B$30+D16*$B$31+E16*$B$32+F16*$B$33 | D32: =C32/B32
A33: Fiyatlandırma | B33: =AVERAGE(B26:F26) | C33: =B17*$B$29+C17*$B$30+D17*$B$31+E17*$B$32+F17*$B$33 | D33: =C33/B33
A34: Toplam | B34: =SUM(B29:B33)
A36: λ_max (ENBÖZD) | B36: =AVERAGE(D29:D33)
A37: n (kriter sayısı) | B37: 5
A38: CI = (λ_max - n) / (n - 1) | B38: =(B36-B37)/(B37-1)
A39: RI (n=5) | B39: 1.11
A40: CR = CI / RI | B40: =B38/B39
A41: Tutarlılık Eşiği | B41: 0.1
A42: Durum | B42: =IF(B40<=B41,"Tutarlı","Tutarsız")

Sheet Katilimci 15
A1: KATILIMCI 15 - AHP ANALİZİ
A3: Demografik Bilgiler
A4: Cinsiyet | B4: =Anket_Yanitlari!B16
A5: Yaş | B5: =Anket_Yanitlari!C16
A6: Eğitim | B6: =Anket_Yanitlari!D16
A7: Meslek | B7: =Anket_Yanitlari!E16
A8: Alışveriş Sıklığı | B8: =Anket_Yanitlari!F16
A9: Cihaz | B9: =Anket_Yanitlari!G16
A11: İkili Karşılaştırma Matrisi (A)
B12: Ödeme | C12: Kullanıcı Deneyimi | D12: Kargo | E12: Müşteri Yorumları | F12: Fiyatlandırma
A13: Ödeme | B13: 1 | C13: =Anket_Yanitlari!H16 | D13: =Anket_Yanitlari!I16 | E13: =Anket_Yanitlari!J16 | F13: =Anket_Yanitlari!K16
A14: Kullanıcı Deneyimi | B14: =1/C13 | C14: 1 | D14: =Anket_Yanitlari!L16 | E14: =Anket_Yanitlari!M16 | F14: =Anket_Yanitlari!N16
A15: Kargo | B15: =1/D13 | C15: =1/D14 | D15: 1 | E15: =Anket_Yanitlari!O16 | F15: =Anket_Yanitlari!P16
A16: Müşteri Yorumları | B16: =1/E13 | C16: =1/E14 | D16: =1/E15 | E16: 1 | F16: =Anket_Yanitlari!Q16
